<robot name = "robot">
    <link name="0">
        <inertial>
            <origin xyz="0 0 0.45925408548607566" rpy="0 0 0"/>
            <mass value="1" />
            <inertia ixx="100" ixy="0" ixz="0" iyy="100" iyz="0" izz="100" />
        </inertial>
        <visual>
            <origin xyz="0 0 0.45925408548607566" rpy="0 0 0"/>
            <geometry>
                <box size="0.2928968529714985 0.6445793546129689 0.9185081709721513" />
            </geometry>
            <material name="Green">
                <color rgba="0 1.0 0 1.0"/>
            </material>
        </visual>
        <collision>
            <origin xyz="0 0 0.45925408548607566" rpy="0 0 0"/>
            <geometry>
                <box size="0.2928968529714985 0.6445793546129689 0.9185081709721513" />
            </geometry>
        </collision>
    </link>
    <joint name="0_1" type="revolute">
       <parent link="0"/>
       <child  link="1"/>
       <origin rpy="0 0 0" xyz="0.061008641079481146 -0.32228967730648445 0.8393274779029354" />
     <axis xyz="1 0 1"/>
       <limit effort="0.0" lower="-3.14159" upper="3.14159" velocity="0.0"/>
    </joint>
    <link name="1">
        <inertial>
            <origin xyz="0 -0.9141845613859751 0.1724508365459426" rpy="0 0 0"/>
            <mass value="1" />
            <inertia ixx="100" ixy="0" ixz="0" iyy="100" iyz="0" izz="100" />
        </inertial>
        <visual>
            <origin xyz="0 -0.9141845613859751 0.1724508365459426" rpy="0 0 0"/>
            <geometry>
                <box size="0.45642671075604974 1.8283691227719503 0.3449016730918852" />
            </geometry>
            <material name="Blue">
                <color rgba="0 0 1.0 1.0"/>
            </material>
        </visual>
        <collision>
            <origin xyz="0 -0.9141845613859751 0.1724508365459426" rpy="0 0 0"/>
            <geometry>
                <box size="0.45642671075604974 1.8283691227719503 0.3449016730918852" />
            </geometry>
        </collision>
    </link>
    <joint name="0_2" type="revolute">
       <parent link="0"/>
       <child  link="2"/>
       <origin rpy="0 0 0" xyz="-0.04989336953441374 -0.32228967730648445 0.14921021898895004" />
     <axis xyz="1 0 1"/>
       <limit effort="0.0" lower="-3.14159" upper="3.14159" velocity="0.0"/>
    </joint>
    <link name="2">
        <inertial>
            <origin xyz="0 -0.8084805835501112 0.06424795561857238" rpy="0 0 0"/>
            <mass value="1" />
            <inertia ixx="100" ixy="0" ixz="0" iyy="100" iyz="0" izz="100" />
        </inertial>
        <visual>
            <origin xyz="0 -0.8084805835501112 0.06424795561857238" rpy="0 0 0"/>
            <geometry>
                <box size="0.3467541262830911 1.6169611671002224 0.12849591123714477" />
            </geometry>
            <material name="Blue">
                <color rgba="0 0 1.0 1.0"/>
            </material>
        </visual>
        <collision>
            <origin xyz="0 -0.8084805835501112 0.06424795561857238" rpy="0 0 0"/>
            <geometry>
                <box size="0.3467541262830911 1.6169611671002224 0.12849591123714477" />
            </geometry>
        </collision>
    </link>
    <joint name="0_3" type="revolute">
       <parent link="0"/>
       <child  link="3"/>
       <origin rpy="0 0 0" xyz="0.06648194463555873 -0.32228967730648445 0.13556296384799651" />
     <axis xyz="1 0 1"/>
       <limit effort="0.0" lower="-3.14159" upper="3.14159" velocity="0.0"/>
    </joint>
    <link name="3">
        <inertial>
            <origin xyz="0 -0.9522106089274227 0.05670080830674426" rpy="0 0 0"/>
            <mass value="1" />
            <inertia ixx="100" ixy="0" ixz="0" iyy="100" iyz="0" izz="100" />
        </inertial>
        <visual>
            <origin xyz="0 -0.9522106089274227 0.05670080830674426" rpy="0 0 0"/>
            <geometry>
                <box size="0.164926619086733 1.9044212178548454 0.11340161661348852" />
            </geometry>
            <material name="Green">
                <color rgba="0 1.0 0 1.0"/>
            </material>
        </visual>
        <collision>
            <origin xyz="0 -0.9522106089274227 0.05670080830674426" rpy="0 0 0"/>
            <geometry>
                <box size="0.164926619086733 1.9044212178548454 0.11340161661348852" />
            </geometry>
        </collision>
    </link>
    <joint name="0_4" type="revolute">
       <parent link="0"/>
       <child  link="4"/>
       <origin rpy="0 0 0" xyz="0.005103686310391514 0.32228967730648445 0.577775172670604" />
     <axis xyz="1 0 1"/>
       <limit effort="0.0" lower="-3.14159" upper="3.14159" velocity="0.0"/>
    </joint>
    <link name="4">
        <inertial>
            <origin xyz="0 0.8345088676984497 0.045280990203287325" rpy="0 0 0"/>
            <mass value="1" />
            <inertia ixx="100" ixy="0" ixz="0" iyy="100" iyz="0" izz="100" />
        </inertial>
        <visual>
            <origin xyz="0 0.8345088676984497 0.045280990203287325" rpy="0 0 0"/>
            <geometry>
                <box size="0.3567700228134316 1.6690177353968993 0.09056198040657465" />
            </geometry>
            <material name="Blue">
                <color rgba="0 0 1.0 1.0"/>
            </material>
        </visual>
        <collision>
            <origin xyz="0 0.8345088676984497 0.045280990203287325" rpy="0 0 0"/>
            <geometry>
                <box size="0.3567700228134316 1.6690177353968993 0.09056198040657465" />
            </geometry>
        </collision>
    </link>
</robot>