<robot name = "robot">
    <link name="0">
        <inertial>
            <origin xyz="-4.0 0 0.4331736298496318" rpy="0 0 0"/>
            <mass value="1" />
            <inertia ixx="100" ixy="0" ixz="0" iyy="100" iyz="0" izz="100" />
        </inertial>
        <visual>
            <origin xyz="-4.0 0 0.4331736298496318" rpy="0 0 0"/>
            <geometry>
                <box size="0.5282407194186273 0.7360883914904093 0.8663472596992636" />
            </geometry>
            <material name="Green">
                <color rgba="0 1.0 0 1.0"/>
            </material>
        </visual>
        <collision>
            <origin xyz="-4.0 0 0.4331736298496318" rpy="0 0 0"/>
            <geometry>
                <box size="0.5282407194186273 0.7360883914904093 0.8663472596992636" />
            </geometry>
        </collision>
    </link>
    <joint name="0_1" type="revolute">
       <parent link="0"/>
       <child  link="1"/>
       <origin rpy="0 0 0" xyz="-3.7358796402906864 0 0.4331736298496318" />
     <axis xyz="0 1 1"/>
       <limit effort="0.0" lower="-3.14159" upper="3.14159" velocity="0.0"/>
    </joint>
    <link name="1">
        <inertial>
            <origin xyz="0.2870594021699473 0 0" rpy="0 0 0"/>
            <mass value="1" />
            <inertia ixx="100" ixy="0" ixz="0" iyy="100" iyz="0" izz="100" />
        </inertial>
        <visual>
            <origin xyz="0.2870594021699473 0 0" rpy="0 0 0"/>
            <geometry>
                <box size="0.5741188043398946 0.8735452910295991 0.6273093833278324" />
            </geometry>
            <material name="Blue">
                <color rgba="0 0 1.0 1.0"/>
            </material>
        </visual>
        <collision>
            <origin xyz="0.2870594021699473 0 0" rpy="0 0 0"/>
            <geometry>
                <box size="0.5741188043398946 0.8735452910295991 0.6273093833278324" />
            </geometry>
        </collision>
    </link>
    <joint name="1_2" type="revolute">
       <parent link="1"/>
       <child  link="2"/>
       <origin rpy="0 0 0" xyz="0.5741188043398946 0 0" />
     <axis xyz="0 1 1"/>
       <limit effort="0.0" lower="-3.14159" upper="3.14159" velocity="0.0"/>
    </joint>
    <link name="2">
        <inertial>
            <origin xyz="0.3921542986552917 0 0" rpy="0 0 0"/>
            <mass value="1" />
            <inertia ixx="100" ixy="0" ixz="0" iyy="100" iyz="0" izz="100" />
        </inertial>
        <visual>
            <origin xyz="0.3921542986552917 0 0" rpy="0 0 0"/>
            <geometry>
                <box size="0.7843085973105834 0.74354718580087 0.5527219001297505" />
            </geometry>
            <material name="Green">
                <color rgba="0 1.0 0 1.0"/>
            </material>
        </visual>
        <collision>
            <origin xyz="0.3921542986552917 0 0" rpy="0 0 0"/>
            <geometry>
                <box size="0.7843085973105834 0.74354718580087 0.5527219001297505" />
            </geometry>
        </collision>
    </link>
    <joint name="2_3" type="revolute">
       <parent link="2"/>
       <child  link="3"/>
       <origin rpy="0 0 0" xyz="0.7843085973105834 0 0" />
     <axis xyz="0 1 1"/>
       <limit effort="0.0" lower="-3.14159" upper="3.14159" velocity="0.0"/>
    </joint>
    <link name="3">
        <inertial>
            <origin xyz="0.473349318994746 0 0" rpy="0 0 0"/>
            <mass value="1" />
            <inertia ixx="100" ixy="0" ixz="0" iyy="100" iyz="0" izz="100" />
        </inertial>
        <visual>
            <origin xyz="0.473349318994746 0 0" rpy="0 0 0"/>
            <geometry>
                <box size="0.946698637989492 0.6822645106790555 0.8735443071400701" />
            </geometry>
            <material name="Green">
                <color rgba="0 1.0 0 1.0"/>
            </material>
        </visual>
        <collision>
            <origin xyz="0.473349318994746 0 0" rpy="0 0 0"/>
            <geometry>
                <box size="0.946698637989492 0.6822645106790555 0.8735443071400701" />
            </geometry>
        </collision>
    </link>
    <joint name="3_4" type="revolute">
       <parent link="3"/>
       <child  link="4"/>
       <origin rpy="0 0 0" xyz="0.946698637989492 0 0" />
     <axis xyz="0 1 1"/>
       <limit effort="0.0" lower="-3.14159" upper="3.14159" velocity="0.0"/>
    </joint>
    <link name="4">
        <inertial>
            <origin xyz="0.4148415812069048 0 0" rpy="0 0 0"/>
            <mass value="1" />
            <inertia ixx="100" ixy="0" ixz="0" iyy="100" iyz="0" izz="100" />
        </inertial>
        <visual>
            <origin xyz="0.4148415812069048 0 0" rpy="0 0 0"/>
            <geometry>
                <box size="0.8296831624138096 0.5777602200935343 0.9544349994404857" />
            </geometry>
            <material name="Green">
                <color rgba="0 1.0 0 1.0"/>
            </material>
        </visual>
        <collision>
            <origin xyz="0.4148415812069048 0 0" rpy="0 0 0"/>
            <geometry>
                <box size="0.8296831624138096 0.5777602200935343 0.9544349994404857" />
            </geometry>
        </collision>
    </link>
    <joint name="4_5" type="revolute">
       <parent link="4"/>
       <child  link="5"/>
       <origin rpy="0 0 0" xyz="0.8296831624138096 0 0" />
     <axis xyz="0 1 1"/>
       <limit effort="0.0" lower="-3.14159" upper="3.14159" velocity="0.0"/>
    </joint>
    <link name="5">
        <inertial>
            <origin xyz="0.4908973761477252 0 0" rpy="0 0 0"/>
            <mass value="1" />
            <inertia ixx="100" ixy="0" ixz="0" iyy="100" iyz="0" izz="100" />
        </inertial>
        <visual>
            <origin xyz="0.4908973761477252 0 0" rpy="0 0 0"/>
            <geometry>
                <box size="0.9817947522954504 0.5061441817515748 0.5957419079518766" />
            </geometry>
            <material name="Blue">
                <color rgba="0 0 1.0 1.0"/>
            </material>
        </visual>
        <collision>
            <origin xyz="0.4908973761477252 0 0" rpy="0 0 0"/>
            <geometry>
                <box size="0.9817947522954504 0.5061441817515748 0.5957419079518766" />
            </geometry>
        </collision>
    </link>
    <joint name="5_6" type="revolute">
       <parent link="5"/>
       <child  link="6"/>
       <origin rpy="0 0 0" xyz="0.9817947522954504 0 0" />
     <axis xyz="0 1 1"/>
       <limit effort="0.0" lower="-3.14159" upper="3.14159" velocity="0.0"/>
    </joint>
    <link name="6">
        <inertial>
            <origin xyz="0.37155057321927826 0 0" rpy="0 0 0"/>
            <mass value="1" />
            <inertia ixx="100" ixy="0" ixz="0" iyy="100" iyz="0" izz="100" />
        </inertial>
        <visual>
            <origin xyz="0.37155057321927826 0 0" rpy="0 0 0"/>
            <geometry>
                <box size="0.7431011464385565 0.8343465064675868 0.5856778018751386" />
            </geometry>
            <material name="Blue">
                <color rgba="0 0 1.0 1.0"/>
            </material>
        </visual>
        <collision>
            <origin xyz="0.37155057321927826 0 0" rpy="0 0 0"/>
            <geometry>
                <box size="0.7431011464385565 0.8343465064675868 0.5856778018751386" />
            </geometry>
        </collision>
    </link>
    <joint name="6_7" type="revolute">
       <parent link="6"/>
       <child  link="7"/>
       <origin rpy="0 0 0" xyz="0.7431011464385565 0 0" />
     <axis xyz="0 1 1"/>
       <limit effort="0.0" lower="-3.14159" upper="3.14159" velocity="0.0"/>
    </joint>
    <link name="7">
        <inertial>
            <origin xyz="0.3977689217732273 0 0" rpy="0 0 0"/>
            <mass value="1" />
            <inertia ixx="100" ixy="0" ixz="0" iyy="100" iyz="0" izz="100" />
        </inertial>
        <visual>
            <origin xyz="0.3977689217732273 0 0" rpy="0 0 0"/>
            <geometry>
                <box size="0.7955378435464546 0.5005661809959465 0.9567753926564982" />
            </geometry>
            <material name="Blue">
                <color rgba="0 0 1.0 1.0"/>
            </material>
        </visual>
        <collision>
            <origin xyz="0.3977689217732273 0 0" rpy="0 0 0"/>
            <geometry>
                <box size="0.7955378435464546 0.5005661809959465 0.9567753926564982" />
            </geometry>
        </collision>
    </link>
    <joint name="7_8" type="revolute">
       <parent link="7"/>
       <child  link="8"/>
       <origin rpy="0 0 0" xyz="0.7955378435464546 0 0" />
     <axis xyz="0 1 1"/>
       <limit effort="0.0" lower="-3.14159" upper="3.14159" velocity="0.0"/>
    </joint>
    <link name="8">
        <inertial>
            <origin xyz="0.4326672863855445 0 0" rpy="0 0 0"/>
            <mass value="1" />
            <inertia ixx="100" ixy="0" ixz="0" iyy="100" iyz="0" izz="100" />
        </inertial>
        <visual>
            <origin xyz="0.4326672863855445 0 0" rpy="0 0 0"/>
            <geometry>
                <box size="0.865334572771089 0.6053489360708226 0.7023306235610842" />
            </geometry>
            <material name="Green">
                <color rgba="0 1.0 0 1.0"/>
            </material>
        </visual>
        <collision>
            <origin xyz="0.4326672863855445 0 0" rpy="0 0 0"/>
            <geometry>
                <box size="0.865334572771089 0.6053489360708226 0.7023306235610842" />
            </geometry>
        </collision>
    </link>
</robot>