<robot name = "robot">
    <link name="0">
        <inertial>
            <origin xyz="0 0 0.25880030256842157" rpy="0 0 0"/>
            <mass value="1" />
            <inertia ixx="100" ixy="0" ixz="0" iyy="100" iyz="0" izz="100" />
        </inertial>
        <visual>
            <origin xyz="0 0 0.25880030256842157" rpy="0 0 0"/>
            <geometry>
                <box size="0.6147621059991187 0.36146532803865805 0.5176006051368431" />
            </geometry>
            <material name="Green">
                <color rgba="0 1.0 0 1.0"/>
            </material>
        </visual>
        <collision>
            <origin xyz="0 0 0.25880030256842157" rpy="0 0 0"/>
            <geometry>
                <box size="0.6147621059991187 0.36146532803865805 0.5176006051368431" />
            </geometry>
        </collision>
    </link>
    <joint name="0_1" type="revolute">
       <parent link="0"/>
       <child  link="1"/>
       <origin rpy="0 0 0" xyz="-0.19906948851281378 -0.18073266401932903 0.00479640756710982" />
     <axis xyz="1 0 1"/>
       <limit effort="0.0" lower="-3.14159" upper="3.14159" velocity="0.0"/>
    </joint>
    <link name="1">
        <inertial>
            <origin xyz="0 -0.5282738514877194 0.10711240914551307" rpy="0 0 0"/>
            <mass value="1" />
            <inertia ixx="100" ixy="0" ixz="0" iyy="100" iyz="0" izz="100" />
        </inertial>
        <visual>
            <origin xyz="0 -0.5282738514877194 0.10711240914551307" rpy="0 0 0"/>
            <geometry>
                <box size="0.43035618573599677 1.0565477029754389 0.21422481829102613" />
            </geometry>
            <material name="Green">
                <color rgba="0 1.0 0 1.0"/>
            </material>
        </visual>
        <collision>
            <origin xyz="0 -0.5282738514877194 0.10711240914551307" rpy="0 0 0"/>
            <geometry>
                <box size="0.43035618573599677 1.0565477029754389 0.21422481829102613" />
            </geometry>
        </collision>
    </link>
    <joint name="0_2" type="revolute">
       <parent link="0"/>
       <child  link="2"/>
       <origin rpy="0 0 0" xyz="0.30738105299955937 -0.020034747542655107 0.12331103147597434" />
     <axis xyz="0 1 1"/>
       <limit effort="0.0" lower="-3.14159" upper="3.14159" velocity="0.0"/>
    </joint>
    <link name="2">
        <inertial>
            <origin xyz="0.5258591158880199 0 0.08872231557414073" rpy="0 0 0"/>
            <mass value="1" />
            <inertia ixx="100" ixy="0" ixz="0" iyy="100" iyz="0" izz="100" />
        </inertial>
        <visual>
            <origin xyz="0.5258591158880199 0 0.08872231557414073" rpy="0 0 0"/>
            <geometry>
                <box size="1.0517182317760398 0.26089153259990117 0.17744463114828146" />
            </geometry>
            <material name="Green">
                <color rgba="0 1.0 0 1.0"/>
            </material>
        </visual>
        <collision>
            <origin xyz="0.5258591158880199 0 0.08872231557414073" rpy="0 0 0"/>
            <geometry>
                <box size="1.0517182317760398 0.26089153259990117 0.17744463114828146" />
            </geometry>
        </collision>
    </link>
    <joint name="0_3" type="revolute">
       <parent link="0"/>
       <child  link="3"/>
       <origin rpy="0 0 0" xyz="0.16598774983211273 -0.18073266401932903 0.1333756150976659" />
     <axis xyz="1 0 1"/>
       <limit effort="0.0" lower="-3.14159" upper="3.14159" velocity="0.0"/>
    </joint>
    <link name="3">
        <inertial>
            <origin xyz="0 -0.7211814605542052 0.1542997672153581" rpy="0 0 0"/>
            <mass value="1" />
            <inertia ixx="100" ixy="0" ixz="0" iyy="100" iyz="0" izz="100" />
        </inertial>
        <visual>
            <origin xyz="0 -0.7211814605542052 0.1542997672153581" rpy="0 0 0"/>
            <geometry>
                <box size="0.4703031966332433 1.4423629211084104 0.3085995344307162" />
            </geometry>
            <material name="Green">
                <color rgba="0 1.0 0 1.0"/>
            </material>
        </visual>
        <collision>
            <origin xyz="0 -0.7211814605542052 0.1542997672153581" rpy="0 0 0"/>
            <geometry>
                <box size="0.4703031966332433 1.4423629211084104 0.3085995344307162" />
            </geometry>
        </collision>
    </link>
    <joint name="0_4" type="revolute">
       <parent link="0"/>
       <child  link="4"/>
       <origin rpy="0 0 0" xyz="0.21454148019838953 -0.18073266401932903 0.09008625755969342" />
     <axis xyz="1 0 1"/>
       <limit effort="0.0" lower="-3.14159" upper="3.14159" velocity="0.0"/>
    </joint>
    <link name="4">
        <inertial>
            <origin xyz="0 -0.7059491729298207 0.04118411527665744" rpy="0 0 0"/>
            <mass value="1" />
            <inertia ixx="100" ixy="0" ixz="0" iyy="100" iyz="0" izz="100" />
        </inertial>
        <visual>
            <origin xyz="0 -0.7059491729298207 0.04118411527665744" rpy="0 0 0"/>
            <geometry>
                <box size="0.3341449737303152 1.4118983458596415 0.08236823055331488" />
            </geometry>
            <material name="Green">
                <color rgba="0 1.0 0 1.0"/>
            </material>
        </visual>
        <collision>
            <origin xyz="0 -0.7059491729298207 0.04118411527665744" rpy="0 0 0"/>
            <geometry>
                <box size="0.3341449737303152 1.4118983458596415 0.08236823055331488" />
            </geometry>
        </collision>
    </link>
    <joint name="0_5" type="revolute">
       <parent link="0"/>
       <child  link="5"/>
       <origin rpy="0 0 0" xyz="0.30738105299955937 -0.158533331609712 0.24830069464724527" />
     <axis xyz="0 1 1"/>
       <limit effort="0.0" lower="-3.14159" upper="3.14159" velocity="0.0"/>
    </joint>
    <link name="5">
        <inertial>
            <origin xyz="0.5752865902489646 0 0.20658453194679544" rpy="0 0 0"/>
            <mass value="1" />
            <inertia ixx="100" ixy="0" ixz="0" iyy="100" iyz="0" izz="100" />
        </inertial>
        <visual>
            <origin xyz="0.5752865902489646 0 0.20658453194679544" rpy="0 0 0"/>
            <geometry>
                <box size="1.1505731804979291 0.020079375727397375 0.41316906389359087" />
            </geometry>
            <material name="Blue">
                <color rgba="0 0 1.0 1.0"/>
            </material>
        </visual>
        <collision>
            <origin xyz="0.5752865902489646 0 0.20658453194679544" rpy="0 0 0"/>
            <geometry>
                <box size="1.1505731804979291 0.020079375727397375 0.41316906389359087" />
            </geometry>
        </collision>
    </link>
    <joint name="0_6" type="revolute">
       <parent link="0"/>
       <child  link="6"/>
       <origin rpy="0 0 0" xyz="0.0051322915335622055 -0.18073266401932903 0.30960425502427313" />
     <axis xyz="1 0 1"/>
       <limit effort="0.0" lower="-3.14159" upper="3.14159" velocity="0.0"/>
    </joint>
    <link name="6">
        <inertial>
            <origin xyz="0 -0.5401994905909215 0.1693464138911594" rpy="0 0 0"/>
            <mass value="1" />
            <inertia ixx="100" ixy="0" ixz="0" iyy="100" iyz="0" izz="100" />
        </inertial>
        <visual>
            <origin xyz="0 -0.5401994905909215 0.1693464138911594" rpy="0 0 0"/>
            <geometry>
                <box size="0.20423898244386496 1.080398981181843 0.3386928277823188" />
            </geometry>
            <material name="Green">
                <color rgba="0 1.0 0 1.0"/>
            </material>
        </visual>
        <collision>
            <origin xyz="0 -0.5401994905909215 0.1693464138911594" rpy="0 0 0"/>
            <geometry>
                <box size="0.20423898244386496 1.080398981181843 0.3386928277823188" />
            </geometry>
        </collision>
    </link>
</robot>